<?xml version='1.0'?>
<robot name="miniBox">

  <!-- Base Link -->
  <link name="base_link">
    <visual>
      <origin xyz="0 0 0" rpy="0 0 0" />
      <geometry>
          <cylinder length="0.2" radius="0.5" />
      </geometry>
      <material name="white">
        <color rgba="1 1 1 1"/>
      </material>
    </visual>
    <!-- Base collision, mass and inertia -->
    <collision>
      <origin xyz="0 0 0" rpy="0 0 0" />
      <geometry>
          <cylinder length="0.2" radius="0.4" />
      </geometry>
    </collision>
    <inertial>
      <mass value="5"/>
      <inertia ixx="0.13" ixy="0.0" ixz="0.0" iyy="0.21" iyz="0.0" izz="0.13"/>
    </inertial>

    <!-- front follow wheel pillar -->
    <visual name="front_follow_wheel_pillar">
      <origin xyz="0.3 0 -0.125" rpy="0 0 0" />
      <geometry>
        <sphere radius="0.075" />
      </geometry>
      
    </visual>
    <!-- collision, mass and inertia -->
    <collision>
      <origin xyz="0.2 0 -0.125" rpy="0 0 0" />
      <geometry>
        <sphere radius="0.05" />
      </geometry>
    </collision>
    <inertial>
      <mass value="0.5"/>
      <inertia ixx="0.0001" ixy="0.0" ixz="0.0" iyy="0.0001" iyz="0.0" izz="0.0001"/>
    </inertial>
  </link>



  <!-- Right Wheel -->
  <link name="right_wheel">
    <visual>
      <origin xyz="0 0 0" rpy="1.570795 0 0" />
      <geometry>
          <cylinder length="0.1" radius="0.2" />
      </geometry>
      <material name="darkgray">
        <color rgba="0.2 0.2 0.2 1"/>
      </material>
    </visual>
    <!-- Right Wheel collision, mass and inertia -->
    <collision>
      <origin xyz="0 0 0" rpy="1.570795 0 0" />
      <geometry>
          <cylinder length="0.1" radius="0.2" />
      </geometry>
    </collision>
    <inertial>
      <mass value="0.5"/>
      <inertia ixx="0.01" ixy="0.0" ixz="0.0" iyy="0.005" iyz="0.0" izz="0.005"/>
    </inertial>

  </link>

  <!-- Right Wheel joint -->
  <joint name="joint_right_wheel" type="continuous">
    <parent link="base_link"/>
    <child link="right_wheel"/>
    <origin xyz="0 -0.30 0" rpy="0 0 0" /> 
    <axis xyz="0 1 0" />
  </joint>

  <!-- Left Wheel -->
  <link name="left_wheel">
    <visual>
      <origin xyz="0 0 0" rpy="1.570795 0 0" />
      <geometry>
          <cylinder length="0.1" radius="0.2" />
      </geometry>
      <material name="darkgray">
        <color rgba="0.2 0.2 0.2 1"/>
      </material>
    </visual>
    <!-- Left Wheel collision, mass and inertia -->
    <collision>
      <origin xyz="0 0 0" rpy="1.570795 0 0" />
      <geometry>
          <cylinder length="0.1" radius="0.2" />
      </geometry>
    </collision>
    <inertial>
      <mass value="0.5"/>
      <inertia ixx="0.01" ixy="0.0" ixz="0.0" iyy="0.005" iyz="0.0" izz="0.005"/>
    </inertial>
  </link>

  <!-- Left Wheel joint -->
  <joint name="joint_left_wheel" type="continuous">
    <parent link="base_link"/>
    <child link="left_wheel"/>
    <origin xyz="0 0.30 0" rpy="0 0 0" /> 
    <axis xyz="0 1 0" />
  </joint>
</robot>